<?xml version="1.0"?>
<robot name="diff_drive">

    <link name="base_footprint" />

    <link name="base_link">
        <visual>
            <origin xyz="0.0 0.0 0.25" rpy="0.0 0.0 0.0" />
            <geometry>
                <mesh filename="file:///home/sanjit/ros2_ws/src/task1/mesh/bot_body.stl"
                    scale="0.25 0.25 0.25" />
            </geometry>1
        </visual>
        <collision>
            <origin xyz="0.0 0.0 0.25" rpy="0.0 0.0 0.0" />
            <geometry>
                <mesh filename="file:///home/sanjit/ros2_ws/src/task1/mesh/bot_body.stl" scale="0.25 0.25 0.25"/>
            </geometry>
        </collision>
        <inertial>
            <origin xyz="0 0 0" rpy="0 0 0" />
            <mass value="3.0" />
            <inertia ixx="0.06" ixy="0.0" ixz="0.0" iyy="0.06" iyz="0.0" izz="0.1" />
        </inertial>

    </link>


    <link name="right_wheel">
        <visual>
            <origin xyz="0.0 0.0 0.0" rpy="0.0 1.57 0.0" />
            <geometry>
                <mesh filename="file:///home/sanjit/ros2_ws/src/task1/mesh/wheel.STL" />
            </geometry>
        </visual>
        <collision>
            <origin xyz="0.0 0.0 0.0" rpy="0.0 1.57 0.0" />
            <geometry>
                <mesh filename="file:///home/sanjit/ros2_ws/src/task1/mesh/wheel.STL" />
            </geometry>
        </collision>
        <inertial>
            <origin xyz="0 0 0" rpy="0 0 0" />
            <mass value="0.5" />
            <inertia ixx="0.00135" ixy="0.0" ixz="0.0" iyy="0.00135" iyz="0.0" izz="0.002" />
        </inertial>
    </link>


    <link name="left_wheel">
        <visual>
            <origin xyz="0.0 0.0 0.0" rpy="0.0 -1.57 0.0" />
            <geometry>
                <mesh filename="file:///home/sanjit/ros2_ws/src/task1/mesh/wheel.STL" />
            </geometry>
        </visual>
        <collision>
            <origin xyz="0.0 0.0 0.0" rpy="0.0 -1.57 0.0" />
            <geometry>
                <mesh filename="file:///home/sanjit/ros2_ws/src/task1/mesh/wheel.STL" />
            </geometry>
        </collision>
        <inertial>
            <origin xyz="0 0 0" rpy="0 0 0" />
            <mass value="0.5" />
            <inertia ixx="0.00135" ixy="0.0" ixz="0.0" iyy="0.00135" iyz="0.0" izz="0.002" />
        </inertial>
    </link>


    <link name="caster_part">
        <visual>
            <origin xyz="0.0 0.0 0.0" rpy="0.0 0.0 0.0" />
            <geometry>
                <mesh filename="file:///home/sanjit/ros2_ws/src/task1/mesh/caster_part.STL"  scale="0.3 0.3 0.3"/>
            </geometry>
        </visual>
        <collision>
            <origin xyz="0.0 0.0 0.0" rpy="0.0 0.0 0.0" />
            <geometry>
                <mesh filename="file:///home/sanjit/ros2_ws/src/task1/mesh/caster_part.STL" scale="0.3 0.3 0.3"/>
            </geometry>
        </collision>
        <inertial>
            <origin xyz="0 0 0" rpy="0 0 0" />
            <mass value="0.5" />
            <inertia ixx="0.00135" ixy="0.0" ixz="0.0" iyy="0.00135" iyz="0.0" izz="0.002" />
        </inertial>
    </link>


    <link name="caster_wheel">
        <visual>
            <origin xyz="0.0 0.0 0.0" rpy="0.0 1.57 0.0" />
            <geometry>
                <mesh filename="file:///home/sanjit/ros2_ws/src/task1/mesh/caster_wheel.STL" scale="0.3 0.3 0.3"/>
            </geometry>
        </visual>
        <collision>
            <origin xyz="0.0 0.0 0.0" rpy="0.0 1.57 0.0" />
            <geometry>
                <mesh filename="file:///home/sanjit/ros2_ws/src/task1/mesh/caster_wheel.STL" scale="0.3 0.3 0.3"/>
            </geometry>
        </collision>
        <inertial>
            <origin xyz="0 0 0" rpy="0 0 0" />
            <mass value="0.5" />
            <inertia ixx="0.001" ixy="0.0" ixz="0.0" iyy="0.001" iyz="0.0" izz="0.002" />
        </inertial>
    </link>

    <gazebo reference="caster_wheel">
        <material>Gazebo/Black</material>
        <mu1>0.001</mu1>
        <mu2>0.001</mu2>
    </gazebo>

    <link name="lidar_cylinder">
        <visual>
            <origin xyz="0.0 0.0 0.0" rpy="0.0 0.0 0.0" />
            <geometry>
                <cylinder radius="0.06" length="0.05" />
            </geometry>
        </visual>
        <collision>
            <origin xyz="0.0 0.0 0.0" rpy="0.0 0.0 0.0" />
            <geometry>
                <cylinder radius="0.06" length="0.05" />
            </geometry>
        </collision>
        <inertial>
            <origin xyz="0 0 0" rpy="0 0 0" />
            <mass value="0.1" />
            <inertia ixx="0.00011" ixy="0.0" ixz="0.0"
                iyy="0.00011" iyz="0.0"
                izz="0.00018" />
        </inertial>
    </link>


    <joint name="base_joint" type="fixed">
        <origin xyz="0.5 0.5 0.0" rpy="0.0 0.0 0.0" />
        <parent link="base_footprint" />
        <child link="base_link" />
    </joint>


    <joint name="left_wheel_joint" type="continuous">
        <origin xyz="-0.4 -0.36 0.14" rpy="0.0 0.0 0.0" />
        <parent link="base_link" />
        <child link="left_wheel" />
        <axis xyz="-1.0 0.0 0.0" />
    </joint>

    <joint name="right_wheel_joint" type="continuous">
        <origin xyz="0.4 -0.36 0.14" rpy="0.0 0.0 0.0" />
        <parent link="base_link" />
        <child link="right_wheel" />
        <axis xyz="-1.0 0.0 0.0" />
    </joint>

    <joint name="part_joint" type="continuous">
        <origin xyz="0.0 0.25 0.0" rpy="-1.57 0.0 0.0" />
        <parent link="base_link" />
        <child link="caster_part" />
        <axis xyz="0.0 1.0 0.0" />
    </joint>

    <joint name="caster_wheel_joint" type="continuous">
        <origin xyz="0.0 0.045 0.02" rpy="0.0 0.0 0.0" />
        <parent link="caster_part" />
        <child link="caster_wheel" />
        <axis xyz="1.0 0.0 0.0" />
    </joint>


    <joint name="lidar_joint" type="fixed">
        <origin xyz="0.0 0 0.5" rpy="0.0 0.0 0.0" />
        <parent link="base_link" />
        <child link="lidar_cylinder" />
        <axis xyz="0.0 0.0 0.0" />
    </joint>


    <gazebo>
        <plugin name="diff_drive_controller" filename="libgazebo_ros_diff_drive.so">
            <ros>
                <namespace></namespace>
            </ros>
            <left_joint>left_wheel_joint</left_joint>
            <right_joint>right_wheel_joint</right_joint>

            <wheel_separation>0.5</wheel_separation>
            <wheel_diameter>0.4</wheel_diameter>

            <max_wheel_torque>10</max_wheel_torque>
            <max_wheel_acceleration>7</max_wheel_acceleration>

            <odometry_frame>odom</odometry_frame>
            <robot_base_frame>base_joint</robot_base_frame>
            <publish_odom>true</publish_odom>
            <publish_odom_tf>true</publish_odom_tf>
            <publish_wheel_tf>true</publish_wheel_tf>
            <cmd_vel_topic>cmd_vel</cmd_vel_topic>
        </plugin>
    </gazebo>

    <gazebo reference="lidar_cylinder">
        <material>Gazebo/Red</material>
        <sensor name="laser" type="ray">
            <pose> 0 0 0 0 0 0 </pose>
            <visualize>false</visualize>
            <update_rate>10</update_rate>
            <ray>
                <scan>
                    <horizontal>
                        <samples>360</samples>
                        <min_angle>-3.14</min_angle>
                        <max_angle>3.14</max_angle>
                    </horizontal>
                </scan>
                <range>
                    <min>0.3</min>
                    <max>12</max>
                </range>
            </ray>
            <plugin name="laser_controller" filename="libgazebo_ros_ray_sensor.so">
                <ros>
                    <argument>~/out:=scan</argument>
                </ros>
                <output_type>sensor_msgs/LaserScan</output_type>
                <frame_name>lidar_cylinder</frame_name>
            </plugin>
        </sensor>
    </gazebo>


</robot>