<?xml version="1.0"?>
<robot name="three_wheel_robot">

    <material name="grey">
        <color rgba="0.7 0.7 0.7 1" />
    </material>

    <material name="green">
        <color rgba="0 1 0 1" />
    </material>

    <link name="base_footprint" />

    <link name="base_link">
        <visual>
            <geometry>
                <box size="0.6 0.4 0.2" />
            </geometry>
            <origin xyz="0 0 0.1" rpy="0 0 0" />
            <material name="green" />
        </visual>
        <collision>
            <origin xyz="0 0 0.1" rpy="0 0 0" />
            <geometry>
                <box size="0.6 0.4 0.2" />
            </geometry>
        </collision>
        <inertial>
            <origin xyz="0 0 0" rpy="0 0 0" />
            <mass value="3.0" />
            <inertia ixx="0.05" ixy="0.0" ixz="0.0"
                iyy="0.1" iyz="0.0"
                izz="0.1" />
        </inertial>
    </link>

    <link name="left_wheel">
        <visual>
            <geometry>
                <cylinder radius="0.1" length="0.05" />
            </geometry>
            <origin xyz="0 0 0" rpy="1.57 0 0" />
            <material name="grey" />
        </visual>
        <collision>
            <geometry>
                <cylinder radius="0.1" length="0.05" />
            </geometry>
            <origin xyz="0 0 0" rpy="1.57 0 0" />
        </collision>
        <inertial>
            <origin xyz="0 0 0" rpy="0 0 0" />
            <mass value="0.5" />
            <inertia ixx="0.0013542" ixy="0.0" ixz="0.0"
                iyy="0.0013542" iyz="0.0"
                izz="0.0025" />
        </inertial>
    </link>

    <link name="right_wheel">
        <visual>
            <geometry>
                <cylinder radius="0.1" length="0.05" />
            </geometry>
            <origin xyz="0 0 0" rpy="1.57 0 0" />
            <material name="grey" />
        </visual>
        <collision>
            <geometry>
                <cylinder radius="0.1" length="0.05" />
            </geometry>
            <origin xyz="0 0 0" rpy="1.57 0 0" />
        </collision>
        <inertial>
            <origin xyz="0 0 0" rpy="0 0 0" />
            <mass value="0.5" />
            <inertia ixx="0.0013542" ixy="0.0" ixz="0.0"
                iyy="0.0013542" iyz="0.0"
                izz="0.0025" />
        </inertial>
    </link>

    <link name="caster_wheel">
        <visual>
            <geometry>
                <sphere radius="0.07" />
            </geometry>
            <origin xyz="0 0 0" rpy="0 0 0" />
            <material name="grey" />
        </visual>
        <collision>
            <geometry>
                <sphere radius="0.07" />
            </geometry>
        </collision>
        <inertial>
            <origin xyz="0 0 0" rpy="0 0 0" />
            <mass value="0.03" />
            <inertia ixx="0.0000588" ixy="0.0" ixz="0.0"
                iyy="0.0000588" iyz="0.0"
                izz="0.0000588" />
        </inertial>
    </link>

    <gazebo reference="caster_wheel">
        <material>Gazebo/Black</material>
        <mu1 value="0.001" />
        <mu2 value="0.001" />
    </gazebo>

    <joint name="base_joint" type="fixed">
        <parent link="base_footprint" />
        <child link="base_link" />
        <origin xyz="0.5 0.5 0.0" rpy="0 0 1.57" />
    </joint>


    <joint name="base_left_wheel_joint" type="continuous">
        <parent link="base_link" />
        <child link="left_wheel" />
        <origin xyz="-0.15 0.225 -0.05" rpy="0 0 0" />
        <axis xyz="0 1 0" />
    </joint>

    <joint name="base_right_wheel_joint" type="continuous">
        <parent link="base_link" />
        <child link="right_wheel" />
        <origin xyz="-0.15 -0.225 -0.05" rpy="0 0 0" />
        <axis xyz="0 1 0" />
    </joint>

    <joint name="base_caster_wheel_joint" type="fixed">
        <parent link="base_link" />
        <child link="caster_wheel" />
        <origin xyz="0.2 0 -0.06" rpy="0 0 0" />
    </joint>

    <!-- Gazebo Properties -->
    <gazebo>
        <plugin name="diff_drive_controller" filename="libgazebo_ros_diff_drive.so">
            <ros>
                <namespace></namespace>
            </ros>
            <left_joint>base_left_wheel_joint</left_joint>
            <right_joint>base_right_wheel_joint</right_joint>

            <wheel_separation>0.6</wheel_separation>
            <wheel_diameter>0.2</wheel_diameter>

            <max_wheel_torque>10</max_wheel_torque>
            <max_wheel_acceleration>7</max_wheel_acceleration>

            <odometry_frame>odom</odometry_frame>
            <robot_base_frame>base_link</robot_base_frame>
            <publish_odom>true</publish_odom>
            <publish_odom_tf>true</publish_odom_tf>
            <publish_wheel_tf>true</publish_wheel_tf>
            <cmd_vel_topic>cmd_vel</cmd_vel_topic>
        </plugin>
    </gazebo>


</robot>